<?xml version="1.0"?>
<robot xmlns:xacro="http://ros.org/wiki/xacro">
    <xacro:include filename="$(find kuka_resources)/urdf/common_constants.xacro"/>
    <xacro:include filename="$(find kuka_resources)/urdf/common_materials.xacro"/>

    <material name="Black">
        <color rgba="0 0 0 1"/>
    </material>

    <material name="White">
        <color rgba="1 1 1 1"/>
    </material>

    <material name="Blue">
        <color rgba="0 0 1 1"/>
    </material>

    <material name="Red">
        <color rgba="1 0 0 1"/>
    </material>

    <!-- Constants -->
    <xacro:property name="M_PI" value="3.14159"/>

    <!-- link1 properties -->
    <xacro:property name="link1_width" value="0.03"/>
    <xacro:property name="link1_len" value="0.10"/>

    <!-- link2 properties -->
    <xacro:property name="link2_width" value="0.03"/>
    <xacro:property name="link2_len" value="0.14"/>

    <!-- link3 properties -->
    <xacro:property name="link3_width" value="0.03"/>
    <xacro:property name="link3_len" value="0.22"/>

    <!-- link4 properties -->
    <xacro:property name="link4_width" value="0.025"/>
    <xacro:property name="link4_len" value="0.06"/>

    <!-- link5 properties -->
    <xacro:property name="link5_width" value="0.03"/>
    <xacro:property name="link5_len" value="0.06"/>

    <!-- link6 properties -->
    <xacro:property name="link6_width" value="0.04"/>
    <xacro:property name="link6_len" value="0.02"/>

    <!-- Left gripper -->
    <xacro:property name="left_gripper_len" value="0.08"/>
    <xacro:property name="left_gripper_width" value="0.01"/>
    <xacro:property name="left_gripper_height" value="0.01"/>

    <!-- Right gripper -->
    <xacro:property name="right_gripper_len" value="0.08"/>
    <xacro:property name="right_gripper_width" value="0.01"/>
    <xacro:property name="right_gripper_height" value="0.01"/>

    <!-- Gripper frame -->
    <xacro:property name="grasp_frame_radius" value="0.001"/>

    <!-- Inertial matrix -->
    <xacro:macro name="inertial_matrix" params="mass">
        <inertial>
            <mass value="${mass}"/>
            <inertia ixx="1.0" ixy="0.0" ixz="0.0" iyy="0.5" iyz="0.0" izz="1.0"/>
        </inertial>
    </xacro:macro>

    <xacro:macro name="transmission_block" params="joint_name">
        <transmission name="tran1">
            <type>transmission_interface/SimpleTransmission</type>
            <joint name="${joint_name}">
                <hardwareInterface>hardware_interface/PositionJointInterface</hardwareInterface>
                <!-- <hardwareInterface>hardware_interface/EffortJointInterface</hardwareInterface> -->
            </joint>
            <actuator name="motor1">
                <hardwareInterface>hardware_interface/PositionJointInterface</hardwareInterface>
                <!-- <hardwareInterface>hardware_interface/EffortJointInterface</hardwareInterface> -->
                <mechanicalReduction>1</mechanicalReduction>
            </actuator>
        </transmission>
    </xacro:macro>

    <xacro:macro name="transmission_effort_block" params="joint_name">
        <transmission name="tran1">
            <type>transmission_interface/SimpleTransmission</type>
            <joint name="${joint_name}">
                <!-- <hardwareInterface>hardware_interface/PositionJointInterface</hardwareInterface> -->
                <hardwareInterface>hardware_interface/EffortJointInterface</hardwareInterface>
            </joint>
            <actuator name="motor1">
                <!-- <hardwareInterface>hardware_interface/PositionJointInterface</hardwareInterface> -->
                <hardwareInterface>hardware_interface/EffortJointInterface</hardwareInterface>
                <mechanicalReduction>1</mechanicalReduction>
            </actuator>
        </transmission>
    </xacro:macro>


    <!-- <xacro:macro name="transmission_vel_block" params="joint_name">
        <transmission name="tran1">
            <type>transmission_interface/SimpleTransmission</type>
            <joint name="${joint_name}">
                <hardwareInterface>hardware_interface/VelocityJointInterface</hardwareInterface>
            </joint>
            <actuator name="motor1">
                <hardwareInterface>hardware_interface/VelocityJointInterface</hardwareInterface>
                <mechanicalReduction>1</mechanicalReduction>
            </actuator>
        </transmission>
    </xacro:macro> -->

    <xacro:macro name="kuka_kr6r700sixx" params="prefix">
        <joint name="${prefix}bottom_joint" type="fixed">
            <origin xyz="0 0 0" rpy="0 0 0"/>
            <parent link="base_link"/>
            <child link="bottom_link"/>
        </joint>

        <link name="${prefix}base_link">
            <visual>
                <origin xyz=" 0 0 0.25" rpy="0 0 0"/>
                <geometry>
                    <box size="0.7 1 0.5"/>
                </geometry>
                <material name="Blue"/>
            </visual>
            <collision>
                <origin xyz=" 0 0 0.25" rpy="0 0 0"/>
                <geometry>
                    <box size="0.7 1 0.5"/>
                </geometry>
            </collision>
            <!-- <xacro:inertial_matrix mass="8000"/> -->
        </link>

        <link name="${prefix}bottom_link">
            <visual>
                <origin xyz="0.1 0 0.49" rpy="0 0 0"/>
                <geometry>
                    <mesh filename="package://kuka_kr6_support/meshes/kr6_agilus/visual/base_link.dae"/>
                </geometry>
                <xacro:material_kuka_pedestal/>
            </visual>
            <collision>
                <origin xyz="0.1 0 0.49" rpy="0 0 0"/>
                <geometry>
                    <mesh filename="package://kuka_kr6_support/meshes/kr6_agilus/collision/base_link.stl"/>
                </geometry>
            </collision>
            <xacro:inertial_matrix mass="500"/>
        </link>
        <link name="${prefix}link1">
            <visual>
                <origin xyz="0 0 0" rpy="0 0 0"/>
                <geometry>
                    <mesh filename="package://kuka_kr6_support/meshes/kr6_agilus/visual/link_1.dae"/>
                </geometry>
                <xacro:material_kuka_orange/>
            </visual>
            <collision>
                <origin xyz="0 0 0" rpy="0 0 0"/>
                <geometry>
                    <mesh filename="package://kuka_kr6_support/meshes/kr6_agilus/collision/link_1.stl"/>
                </geometry>
            </collision>
            <xacro:inertial_matrix mass="1"/>
        </link>
        <link name="${prefix}link2">
            <visual>
                <origin xyz="0 0 0" rpy="0 0 0"/>
                <geometry>
                    <mesh filename="package://kuka_kr6_support/meshes/kr6r700sixx/visual/link_2.dae"/>
                </geometry>
                <xacro:material_kuka_orange/>
            </visual>
            <collision>
                <origin xyz="0 0 0" rpy="0 0 0"/>
                <geometry>
                    <mesh filename="package://kuka_kr6_support/meshes/kr6r700sixx/collision/link_2.stl"/>
                </geometry>
            </collision>
            <xacro:inertial_matrix mass="1"/>
        </link>
        <link name="${prefix}link3">
            <visual>
                <origin xyz="0 0 0" rpy="0 0 0"/>
                <geometry>
                    <mesh filename="package://kuka_kr6_support/meshes/kr6_agilus/visual/link_3.dae"/>
                </geometry>
                <xacro:material_kuka_orange/>
            </visual>
            <collision>
                <origin xyz="0 0 0" rpy="0 0 0"/>
                <geometry>
                    <mesh filename="package://kuka_kr6_support/meshes/kr6_agilus/collision/link_3.stl"/>
                </geometry>
            </collision>
            <xacro:inertial_matrix mass="1"/>
        </link>
        <link name="${prefix}link4">
            <visual>
                <origin xyz="0 0 0" rpy="0 0 0"/>
                <geometry>
                    <mesh filename="package://kuka_kr6_support/meshes/kr6r700sixx/visual/link_4.dae"/>
                </geometry>
                <xacro:material_kuka_orange/>
            </visual>
            <collision>
                <origin xyz="0 0 0" rpy="0 0 0"/>
                <geometry>
                    <mesh filename="package://kuka_kr6_support/meshes/kr6r700sixx/collision/link_4.stl"/>
                </geometry>
            </collision>
            <xacro:inertial_matrix mass="1"/>
        </link>
        <link name="${prefix}link5">
            <visual>
                <origin xyz="0 0 0" rpy="0 0 0"/>
                <geometry>
                    <mesh filename="package://kuka_kr6_support/meshes/kr6_agilus/visual/link_5.dae"/>
                </geometry>
                <xacro:material_kuka_orange/>
            </visual>
            <collision>
                <origin xyz="0 0 0" rpy="0 0 0"/>
                <geometry>
                    <mesh filename="package://kuka_kr6_support/meshes/kr6_agilus/collision/link_5.stl"/>
                </geometry>
            </collision>
            <xacro:inertial_matrix mass="1"/>
        </link>
        <link name="${prefix}link6">
            <visual>
                <origin xyz="0 0 0" rpy="0 0 0"/>
                <geometry>
                    <mesh filename="package://kuka_kr6_support/meshes/kr6_agilus/visual/link_6.dae"/>
                </geometry>
                <xacro:material_kuka_pedestal/>
            </visual>
            <collision>
                <origin xyz="0 0 0" rpy="0 0 0"/>
                <geometry>
                    <mesh filename="package://kuka_kr6_support/meshes/kr6_agilus/collision/link_6.stl"/>
                </geometry>
            </collision>
            <xacro:inertial_matrix mass="1"/>
        </link>
        <!-- This frame corresponds to the $FLANGE coordinate system in KUKA KRC controllers. -->
        <!--        <link name="${prefix}tool0"/>-->

        <joint name="${prefix}joint1" type="revolute">
            <origin xyz="0.1 0 0.89" rpy="0 0 0"/>
            <parent link="${prefix}bottom_link"/>
            <child link="${prefix}link1"/>
            <axis xyz="0 0 -1"/>
            <limit lower="${-170 * DEG2RAD}" upper="${170 * DEG2RAD}" effort="0" velocity="${360 * DEG2RAD}"/>
        </joint>
        <joint name="${prefix}joint2" type="revolute">
            <origin xyz="0.025 0 0" rpy="0 0 0"/>
            <parent link="${prefix}link1"/>
            <child link="${prefix}link2"/>
            <axis xyz="0 1 0"/>
            <limit lower="${-190 * DEG2RAD}" upper="${45 * DEG2RAD}" effort="0" velocity="${300 * DEG2RAD}"/>
        </joint>
        <joint name="${prefix}joint3" type="revolute">
            <origin xyz="0.315 0 0" rpy="0 ${-M_PI*2/3} 0"/>
            <parent link="${prefix}link2"/>
            <child link="${prefix}link3"/>
            <axis xyz="0 1 0"/>
            <limit lower="${-120 * DEG2RAD + M_PI*2/3}" upper="${156 * DEG2RAD + M_PI*2/3}" effort="0"
                   velocity="${360 * DEG2RAD}"/>
        </joint>
        <joint name="${prefix}joint4" type="revolute">
            <origin xyz="0 0 0.035" rpy="0 0 0"/>
            <parent link="${prefix}link3"/>
            <child link="${prefix}link4"/>
            <axis xyz="-1 0 0"/>
            <limit lower="${-185 * DEG2RAD}" upper="${185 * DEG2RAD}" effort="0" velocity="${381 * DEG2RAD}"/>
        </joint>
        <joint name="${prefix}joint5" type="revolute">
            <origin xyz="0.365 0 0" rpy="0 0 0"/>
            <parent link="${prefix}link4"/>
            <child link="${prefix}link5"/>
            <axis xyz="0 1 0"/>
            <limit lower="${-120 * DEG2RAD}" upper="${120 * DEG2RAD}" effort="0" velocity="${388 * DEG2RAD}"/>
        </joint>
        <joint name="${prefix}joint6" type="revolute">
            <origin xyz="0.080 0 0" rpy="0 0 0"/>
            <parent link="${prefix}link5"/>
            <child link="${prefix}link6"/>
            <axis xyz="-1 0 0"/>
            <limit lower="${-350 * DEG2RAD}" upper="${350 * DEG2RAD}" effort="0" velocity="${615 * DEG2RAD}"/>
        </joint>

        <!--        <joint name="${prefix}joint_a6-tool0" type="fixed">-->
        <!--            <parent link="${prefix}link6"/>-->
        <!--            <child link="${prefix}tool0"/>-->
        <!--            <origin xyz="0 0 0" rpy="0 ${90 * DEG2RAD} 0"/>-->
        <!--        </joint>-->

<!--        ROS base_link to KUKA $ROBROOT coordinate system transform-->
        <link name="${prefix}base"/>
        <joint name="${prefix}base_link-base" type="fixed">
            <origin xyz="0 0 0" rpy="0 0 0"/>
            <parent link="${prefix}base_link"/>
            <child link="${prefix}base"/>
        </joint>

        <!--        <joint name="${prefix}finger_joint1" type="prismatic">-->
        <!--            <parent link="${prefix}link6"/>-->
        <!--            <child link="${prefix}gripper_finger_link1"/>-->
        <!--            <origin xyz="0.0 0 0"/>-->
        <!--            <axis xyz="0 1 0"/>-->
        <!--            <limit effort="100" lower="0" upper="0.06" velocity="1.0"/>-->
        <!--            <dynamics damping="50" friction="1"/>-->
        <!--        </joint>-->

        <!-- //////////////////////////////////////   gripper   ////////////////////////////////////////////// -->
        <!-- LEFT GRIPPER AFT LINK -->
        <!--        <link name="${prefix}gripper_finger_link1">-->
        <!--            <visual>-->
        <!--                <origin xyz="0.04 -0.04 0" rpy="0 0 0"/>-->
        <!--                <geometry>-->
        <!--                    <box size="${left_gripper_len} ${left_gripper_width} ${left_gripper_height}"/>-->
        <!--                </geometry>-->
        <!--                <material name="White"/>-->
        <!--            </visual>-->
        <!--            <collision>-->
        <!--                <origin xyz="0.04 -0.04 0" rpy="0 0 0"/>-->
        <!--                <geometry>-->
        <!--                    <box size="${left_gripper_len} ${left_gripper_width} ${left_gripper_height}"/>-->
        <!--                </geometry>-->
        <!--            </collision>-->
        <!--            <xacro:inertial_matrix mass="1"/>-->
        <!--        </link>-->

        <!--        <joint name="${prefix}finger_joint2" type="fixed">-->
        <!--            <parent link="${prefix}link6"/>-->
        <!--            <child link="${prefix}gripper_finger_link2"/>-->
        <!--            <origin xyz="0.0 0 0"/>-->
        <!--        </joint>-->

        <!--        &lt;!&ndash; RIGHT GRIPPER AFT LINK &ndash;&gt;-->
        <!--        <link name="${prefix}gripper_finger_link2">-->
        <!--            <visual>-->
        <!--                <origin xyz="0.04 0.04 0" rpy="0 0 0"/>-->
        <!--                <geometry>-->
        <!--                    <box size="${right_gripper_len} ${right_gripper_width} ${right_gripper_height}"/>-->
        <!--                </geometry>-->
        <!--                <material name="White"/>-->
        <!--            </visual>-->
        <!--            <collision>-->
        <!--                <origin xyz="0.04 0.04 0" rpy="0 0 0"/>-->
        <!--                <geometry>-->
        <!--                    <box size="${right_gripper_len} ${right_gripper_width} ${right_gripper_height}"/>-->
        <!--                </geometry>-->
        <!--            </collision>-->
        <!--            <xacro:inertial_matrix mass="1"/>-->
        <!--        </link>-->

        <!-- Grasping frame -->
        <link name="${prefix}grasping_frame"/>

        <joint name="${prefix}grasping_frame_joint" type="fixed">
            <parent link="${prefix}link6"/>
            <child link="${prefix}grasping_frame"/>
            <origin xyz="0.1 0 0" rpy="0 0 0"/>
        </joint>

        <gazebo reference="${prefix}bottom_link">
            <xacro:material_kuka_pedestal/>
        </gazebo>
        <gazebo reference="${prefix}base_link">
            <material>Gazebo/Blue</material>
        </gazebo>
        <gazebo reference="${prefix}link1">
            <xacro:material_kuka_orange/>
        </gazebo>
        <gazebo reference="${prefix}link2">
            <xacro:material_kuka_orange/>
        </gazebo>
        <gazebo reference="${prefix}link3">
            <xacro:material_kuka_orange/>
        </gazebo>
        <gazebo reference="${prefix}link4">
            <xacro:material_kuka_orange/>
        </gazebo>
        <gazebo reference="${prefix}link5">
            <xacro:material_kuka_orange/>
        </gazebo>
        <gazebo reference="${prefix}link6">
            <xacro:material_kuka_orange/>
        </gazebo>
        <gazebo reference="${prefix}base">
            <xacro:material_kuka_orange/>
        </gazebo>
        <!--        <gazebo reference="${prefix}gripper_finger_link1">-->
        <!--            <mu1 value="200.0"/>-->
        <!--            <mu2 value="100.0"/>-->
        <!--            <kp value="1000000.0"/>-->
        <!--            <kd value="1.0"/>-->
        <!--            <material>Gazebo/White</material>-->
        <!--        </gazebo>-->
        <!--        <gazebo reference="${prefix}gripper_finger_link2">-->
        <!--            <mu1 value="200.0"/>-->
        <!--            <mu2 value="100.0"/>-->
        <!--            <kp value="1000000.0"/>r-->
        <!--            <kd value="1.0"/>-->
        <!--            <material>Gazebo/White</material>-->
        <!--        </gazebo>-->

        <xacro:transmission_block joint_name="${prefix}joint1"/>
        <xacro:transmission_block joint_name="${prefix}joint2"/>
        <xacro:transmission_block joint_name="${prefix}joint3"/>
        <xacro:transmission_block joint_name="${prefix}joint4"/>
        <xacro:transmission_block joint_name="${prefix}joint5"/>
        <xacro:transmission_block joint_name="${prefix}joint6"/>

        <!-- <xacro:transmission_effort_block joint_name="${prefix}joint1"/>
        <xacro:transmission_effort_block joint_name="${prefix}joint2"/>
        <xacro:transmission_effort_block joint_name="${prefix}joint3"/>
        <xacro:transmission_effort_block joint_name="${prefix}joint4"/>
        <xacro:transmission_effort_block joint_name="${prefix}joint5"/>
        <xacro:transmission_effort_block joint_name="${prefix}joint6"/> -->


        <gazebo>
            <plugin name="gazebo_ros_control" filename="libgazebo_ros_control.so">
                <robotNamespace>/arm</robotNamespace>
                <legacyModeNS>true</legacyModeNS>
            </plugin>
        </gazebo>
    </xacro:macro>
</robot>
